Workbook
Name Slicer_Days: #N/A
Name Slicer_Month: #N/A
Name Slicer_Opportunity_Pipeline: #N/A
Name Slicer_Year: #N/A

Sheet DASHBOARD Light

Sheet DASHBOARD

Sheet Processing
A1: Previous | B1: Levels | C1: Sales Funnel | D1: Conversion | F1: KPI | G1: KPI Plan | H1: ↑ | I1: ↓ | J1: Alt+254 | K1: Won Deals | L1: Pending | M1: Lost | O1: Sales Cycle | P1: Duration | Q1: Label
A2: =GETPIVOTDATA("Prev "&B2,Control!$A$3) -> 2986 | B2: Leads | C2: =GETPIVOTDATA(""&B2,Control!$A$3) -> 1223 | D2: =C3/C2 -> 0.52493868 | E2: =1-D2 -> 0.47506132 | F2: =D2/G2 -> 1.3123467 | G2: 0.4 | H2: =IF(C2>A2,$J$2,"") | I2: =IF(C2<A2,$J$2,"") -> ■ | J2: ■ | K2: =GETPIVOTDATA(""&K1,Control!$A$3) -> 103686 | L2: =GETPIVOTDATA(""&L1,Control!$A$3) -> 192011 | M2: =GETPIVOTDATA(""&M1,Control!$A$3) -> 19201 | O2: 7 | P2: =GETPIVOTDATA("Average of Duration",Control!$A$3) -> 5.4 | Q2: =O2&" Days" -> 7 Days
A3: =GETPIVOTDATA("Prev "&B3,Control!$A$3) -> 865 | B3: MQL | C3: =GETPIVOTDATA(""&B3,Control!$A$3) -> 642 | D3: =C4/C3 -> 0.76479751 | E3: =1-D3 -> 0.23520249 | F3: =D3/G3 -> 1.529595 | G3: 0.5 | H3: =IF(C3>A3,$J$2,"") | I3: =IF(C3<A3,$J$2,"") -> ■ | J3: SHARE | K3: =K2/SUM($K$2:$M$2) -> 0.32926853 | L3: =L2/SUM($K$2:$M$2) -> 0.60975618 | M3: =M2/SUM($K$2:$M$2) -> 0.0609753 | O3: =P2/O2 -> 0.77142857 | P3: =1-O3 -> 0.22857143 | Q3: =P2&" Days" -> 5.4 Days
A4: =GETPIVOTDATA("Prev "&B4,Control!$A$3) -> 573 | B4: SQL | C4: =GETPIVOTDATA(""&B4,Control!$A$3) -> 491 | D4: =C5/C4 -> 0.46639511 | E4: =1-D4 -> 0.53360489 | F4: =D4/G4 -> 0.62186015 | G4: 0.75 | H4: =IF(C4>A4,$J$2,"") | I4: =IF(C4<A4,$J$2,"") -> ■
A5: =GETPIVOTDATA("Prev "&B5,Control!$A$3) -> 305 | B5: Opportunity | C5: =GETPIVOTDATA(""&B5,Control!$A$3) -> 229 | D5: =C6/C5 -> 0.34061135 | E5: =1-D5 -> 0.65938865 | F5: =D5/G5 -> 0.9731753 | G5: 0.35 | H5: =IF(C5>A5,$J$2,"") | I5: =IF(C5<A5,$J$2,"") -> ■ | O5: Risk Aging
A6: =GETPIVOTDATA("Prev "&B6,Control!$A$3) -> 95 | B6: Deals | C6: =GETPIVOTDATA(""&B6,Control!$A$3) -> 78 | H6: =IF(C6>A6,$J$2,"") | I6: =IF(C6<A6,$J$2,"") -> ■ | O6: =GETPIVOTDATA("Average of Risk Aging",Control!$A$3) -> 0.14 | P6: =1-O6 -> 0.86
A7: Revenue / Forecast | H7: Days | I7: Weekly Activity | J7: Cursor | K7: Day | L7: Returning | M7: New Clients
A8: Month | B8: Revenue | C8: Cursor | D8: Forecast | H8: Sun | I8: =GETPIVOTDATA(""&H8,Control!$A$3) -> 0.1 | J8: =IF(ISNUMBER(MATCH(H8,Control!$A$45:$A$51,0)),I8,NA()) -> #N/A | K8: 1 | L8: =GETPIVOTDATA(""&K8,Control!$A$3) -> 1 | M8: =GETPIVOTDATA("1"&K8,Control!$A$3) -> 0.12 | O8: =I8/$J$15 -> 0.5
A9: JAN | B9: =GETPIVOTDATA(""&B$8,Control!$A$20,"Month",""&$A9) -> 620194 | C9: =IFERROR(GETPIVOTDATA(""&B$8,Control!$A$3,"Month",""&$A9),NA()) -> #N/A | D9: =GETPIVOTDATA(""&D$8,Control!$A$20,"Month",""&$A9) -> 950198 | H9: Mon | I9: =GETPIVOTDATA(""&H9,Control!$A$3) -> 0.1 | J9: =IF(ISNUMBER(MATCH(H9,Control!$A$45:$A$51,0)),I9,NA()) -> #N/A | K9: 2 | L9: =GETPIVOTDATA(""&K9,Control!$A$3) -> 0.6 | M9: =GETPIVOTDATA("1"&K9,Control!$A$3) -> 0.34 | O9: =I9/$J$15 -> 0.5
A10: FEB | B10: =GETPIVOTDATA(""&B$8,Control!$A$20,"Month",""&$A10) -> 750285 | C10: =IFERROR(GETPIVOTDATA(""&B$8,Control!$A$3,"Month",""&$A10),NA()) -> #N/A | D10: =GETPIVOTDATA(""&D$8,Control!$A$20,"Month",""&$A10) -> 800198 | H10: Tue | I10: =GETPIVOTDATA(""&H10,Control!$A$3) -> 0.15 | J10: =IF(ISNUMBER(MATCH(H10,Control!$A$45:$A$51,0)),I10,NA()) -> #N/A | K10: 3 | L10: =GETPIVOTDATA(""&K10,Control!$A$3) -> 0.51 | M10: =GETPIVOTDATA("1"&K10,Control!$A$3) -> 0.3 | O10: =I10/$J$15 -> 0.75
A11: MAR | B11: =GETPIVOTDATA(""&B$8,Control!$A$20,"Month",""&$A11) -> 880309 | C11: =IFERROR(GETPIVOTDATA(""&B$8,Control!$A$3,"Month",""&$A11),NA()) -> #N/A | D11: =GETPIVOTDATA(""&D$8,Control!$A$20,"Month",""&$A11) -> 700366 | H11: Wed | I11: =GETPIVOTDATA(""&H11,Control!$A$3) -> 0.18 | J11: =IF(ISNUMBER(MATCH(H11,Control!$A$45:$A$51,0)),I11,NA()) -> 0.18 | K11: 4 | L11: =GETPIVOTDATA(""&K11,Control!$A$3) -> 0.79 | M11: =GETPIVOTDATA("1"&K11,Control!$A$3) -> 0.44 | O11: =I11/$J$15 -> 0.9
A12: APR | B12: =GETPIVOTDATA(""&B$8,Control!$A$20,"Month",""&$A12) -> 1020288 | C12: =IFERROR(GETPIVOTDATA(""&B$8,Control!$A$3,"Month",""&$A12),NA()) -> #N/A | D12: =GETPIVOTDATA(""&D$8,Control!$A$20,"Month",""&$A12) -> 650158 | H12: Thu | I12: =GETPIVOTDATA(""&H12,Control!$A$3) -> 0.15 | J12: =IF(ISNUMBER(MATCH(H12,Control!$A$45:$A$51,0)),I12,NA()) -> #N/A | K12: 5 | L12: =GETPIVOTDATA(""&K12,Control!$A$3) -> 0.69 | M12: =GETPIVOTDATA("1"&K12,Control!$A$3) -> 0.48 | O12: =I12/$J$15 -> 0.75
A13: MAY | B13: =GETPIVOTDATA(""&B$8,Control!$A$20,"Month",""&$A13) -> 1150282 | C13: =IFERROR(GETPIVOTDATA(""&B$8,Control!$A$3,"Month",""&$A13),NA()) -> #N/A | D13: =GETPIVOTDATA(""&D$8,Control!$A$20,"Month",""&$A13) -> 550211 | H13: Fri | I13: =GETPIVOTDATA(""&H13,Control!$A$3) -> 0.14 | J13: =IF(ISNUMBER(MATCH(H13,Control!$A$45:$A$51,0)),I13,NA()) -> #N/A | K13: 6 | L13: =GETPIVOTDATA(""&K13,Control!$A$3) -> 0.4 | M13: =GETPIVOTDATA("1"&K13,Control!$A$3) -> 0.56 | O13: =I13/$J$15 -> 0.7
A14: JUN | B14: =GETPIVOTDATA(""&B$8,Control!$A$20,"Month",""&$A14) -> 1100350 | C14: =IFERROR(GETPIVOTDATA(""&B$8,Control!$A$3,"Month",""&$A14),NA()) -> #N/A | D14: =GETPIVOTDATA(""&D$8,Control!$A$20,"Month",""&$A14) -> 600367 | H14: Sat | I14: =GETPIVOTDATA(""&H14,Control!$A$3) -> 0.17 | J14: =IF(ISNUMBER(MATCH(H14,Control!$A$45:$A$51,0)),I14,NA()) -> #N/A | K14: 7 | L14: =GETPIVOTDATA(""&K14,Control!$A$3) -> 0.01 | M14: =GETPIVOTDATA("1"&K14,Control!$A$3) -> 1 | O14: =I14/$J$15 -> 0.85
A15: JUL | B15: =GETPIVOTDATA(""&B$8,Control!$A$20,"Month",""&$A15) -> 950350 | C15: =IFERROR(GETPIVOTDATA(""&B$8,Control!$A$3,"Month",""&$A15),NA()) -> #N/A | D15: =GETPIVOTDATA(""&D$8,Control!$A$20,"Month",""&$A15) -> 750365 | J15: =GETPIVOTDATA("Weekly Activity",Control!$A$44) -> 0.2
A16: AUG | B16: =GETPIVOTDATA(""&B$8,Control!$A$20,"Month",""&$A16) -> 850346 | C16: =IFERROR(GETPIVOTDATA(""&B$8,Control!$A$3,"Month",""&$A16),NA()) -> #N/A | D16: =GETPIVOTDATA(""&D$8,Control!$A$20,"Month",""&$A16) -> 900163 | F16: Opportunity Pipeline | G16: Value | H16: Count | I16: Cursor | L16: Retention Rate
A17: SEP | B17: =GETPIVOTDATA(""&B$8,Control!$A$20,"Month",""&$A17) -> 700391 | C17: =IFERROR(GETPIVOTDATA(""&B$8,Control!$A$3,"Month",""&$A17),NA()) -> #N/A | D17: =GETPIVOTDATA(""&D$8,Control!$A$20,"Month",""&$A17) -> 1000261 | F17: Qualify | G17: =GETPIVOTDATA(""&F17,Control!$A$3) -> 776529 | H17: =C5 -> 229 | I17: =IF(ISNUMBER(MATCH(F17,Control!$A$38:$A$41,0)),Processing!G17,NA()) -> #N/A | L17: =GETPIVOTDATA("Average of Retention Rate",Control!$A$3) -> 0.61 | M17: =100%-L17 -> 0.39
A18: OCT | B18: =GETPIVOTDATA(""&B$8,Control!$A$20,"Month",""&$A18) -> 650203 | C18: =IFERROR(GETPIVOTDATA(""&B$8,Control!$A$3,"Month",""&$A18),NA()) -> 650203 | D18: =GETPIVOTDATA(""&D$8,Control!$A$20,"Month",""&$A18) -> 850387 | F18: Proposal | G18: =GETPIVOTDATA(""&F18,Control!$A$3) -> 499863 | H18: =GETPIVOTDATA(F18&" "&$H$16,Control!$A$3) -> 159 | I18: =IF(ISNUMBER(MATCH(F18,Control!$A$38:$A$41,0)),Processing!G18,NA()) -> 499863
A19: NOV | B19: =GETPIVOTDATA(""&B$8,Control!$A$20,"Month",""&$A19) -> 800355 | C19: =IFERROR(GETPIVOTDATA(""&B$8,Control!$A$3,"Month",""&$A19),NA()) -> #N/A | D19: =GETPIVOTDATA(""&D$8,Control!$A$20,"Month",""&$A19) -> 700382 | F19: Negotiation | G19: =GETPIVOTDATA(""&F19,Control!$A$3) -> 443276 | H19: =GETPIVOTDATA(F19&" "&$H$16,Control!$A$3) -> 123 | I19: =IF(ISNUMBER(MATCH(F19,Control!$A$38:$A$41,0)),Processing!G19,NA()) -> #N/A
A20: DEC | B20: =GETPIVOTDATA(""&B$8,Control!$A$20,"Month",""&$A20) -> 900113 | C20: =IFERROR(GETPIVOTDATA(""&B$8,Control!$A$3,"Month",""&$A20),NA()) -> #N/A | D20: =GETPIVOTDATA(""&D$8,Control!$A$20,"Month",""&$A20) -> 600384 | F20: Closed | G20: =K2 -> 103686 | H20: =C6 -> 78 | I20: =IF(ISNUMBER(MATCH(F20,Control!$A$38:$A$41,0)),Processing!G20,NA()) -> #N/A
B21: KPI | C21: Actual | D21: Target | H21: =MAX(H17:H20)*150% -> 343.5 | I21: =GETPIVOTDATA("Value",Control!$A$37) -> 588164
B22: =C22/D22 -> 0.76459659 | C22: =GETPIVOTDATA("Sum of Revenue",Control!$A$3) -> 650203 | D22: =GETPIVOTDATA("Sum of Forecast",Control!$A$3) -> 850387
B24: Sales Team | G24: Marketing Team
A25: 1 | B25: Ethan | C25: Michael | D25: James | E25: Olivia | F25: Emma | G25: Daniel | H25: Ryan | I25: Sophia | J25: Ava | K25: Madison | L25: Sort | M25: Manager | N25: Value1 | O25: Value2
A26: Top-1 | B26: =($L26=B$31)*10*($A$25=1) -> 10 | C26: =($L26=C$31)*10*($A$25=1) -> 0 | D26: =($L26=D$31)*10*($A$25=1) -> 0 | E26: =($L26=E$31)*10*($A$25=1) -> 0 | F26: =($L26=F$31)*10*($A$25=1) -> 0 | G26: =($L26=G$31)*10*($A$25=2) -> 0 | H26: =($L26=H$31)*10*($A$25=2) -> 0 | I26: =($L26=I$31)*10*($A$25=2) -> 0 | J26: =($L26=J$31)*10*($A$25=2) -> 0 | K26: =($L26=K$31)*10*($A$25=2) -> 0 | L26: {=INDEX(CHOOSE($A$25,$E$34:$E$38,$E$41:$E$45),A34)} -> 1 | M26: {=INDEX(CHOOSE($A$25,$F$34:$F$38,$F$41:$F$45),A34)} -> Ethan | N26: =CHOOSE($A$25,G34,TEXT(G41,"0%")) -> 23076 | O26: =CHOOSE($A$25,"",G41)
A27: Top-2 | B27: =($L27=B$31)*10*($A$25=1) -> 0 | C27: =($L27=C$31)*10*($A$25=1) -> 0 | D27: =($L27=D$31)*10*($A$25=1) -> 10 | E27: =($L27=E$31)*10*($A$25=1) -> 0 | F27: =($L27=F$31)*10*($A$25=1) -> 0 | G27: =($L27=G$31)*10*($A$25=2) -> 0 | H27: =($L27=H$31)*10*($A$25=2) -> 0 | I27: =($L27=I$31)*10*($A$25=2) -> 0 | J27: =($L27=J$31)*10*($A$25=2) -> 0 | K27: =($L27=K$31)*10*($A$25=2) -> 0 | L27: {=INDEX(CHOOSE($A$25,$E$34:$E$38,$E$41:$E$45),A35)} -> 3 | M27: {=INDEX(CHOOSE($A$25,$F$34:$F$38,$F$41:$F$45),A35)} -> James | N27: =CHOOSE($A$25,G35,TEXT(G42,"0%")) -> 22452 | O27: =CHOOSE($A$25,"",G42)
A28: Top-3 | B28: =($L28=B$31)*10*($A$25=1) -> 0 | C28: =($L28=C$31)*10*($A$25=1) -> 0 | D28: =($L28=D$31)*10*($A$25=1) -> 0 | E28: =($L28=E$31)*10*($A$25=1) -> 0 | F28: =($L28=F$31)*10*($A$25=1) -> 10 | G28: =($L28=G$31)*10*($A$25=2) -> 0 | H28: =($L28=H$31)*10*($A$25=2) -> 0 | I28: =($L28=I$31)*10*($A$25=2) -> 0 | J28: =($L28=J$31)*10*($A$25=2) -> 0 | K28: =($L28=K$31)*10*($A$25=2) -> 0 | L28: {=INDEX(CHOOSE($A$25,$E$34:$E$38,$E$41:$E$45),A36)} -> 5 | M28: {=INDEX(CHOOSE($A$25,$F$34:$F$38,$F$41:$F$45),A36)} -> Emma | N28: =CHOOSE($A$25,G36,TEXT(G43,"0%")) -> 20737 | O28: =CHOOSE($A$25,"",G43)
A29: Top-4 | B29: =($L29=B$31)*10*($A$25=1) -> 0 | C29: =($L29=C$31)*10*($A$25=1) -> 0 | D29: =($L29=D$31)*10*($A$25=1) -> 0 | E29: =($L29=E$31)*10*($A$25=1) -> 10 | F29: =($L29=F$31)*10*($A$25=1) -> 0 | G29: =($L29=G$31)*10*($A$25=2) -> 0 | H29: =($L29=H$31)*10*($A$25=2) -> 0 | I29: =($L29=I$31)*10*($A$25=2) -> 0 | J29: =($L29=J$31)*10*($A$25=2) -> 0 | K29: =($L29=K$31)*10*($A$25=2) -> 0 | L29: {=INDEX(CHOOSE($A$25,$E$34:$E$38,$E$41:$E$45),A37)} -> 4 | M29: {=INDEX(CHOOSE($A$25,$F$34:$F$38,$F$41:$F$45),A37)} -> Olivia | N29: =CHOOSE($A$25,G37,TEXT(G44,"0%")) -> 19334 | O29: =CHOOSE($A$25,"",G44)
A30: Top-5 | B30: =($L30=B$31)*10*($A$25=1) -> 0 | C30: =($L30=C$31)*10*($A$25=1) -> 10 | D30: =($L30=D$31)*10*($A$25=1) -> 0 | E30: =($L30=E$31)*10*($A$25=1) -> 0 | F30: =($L30=F$31)*10*($A$25=1) -> 0 | G30: =($L30=G$31)*10*($A$25=2) -> 0 | H30: =($L30=H$31)*10*($A$25=2) -> 0 | I30: =($L30=I$31)*10*($A$25=2) -> 0 | J30: =($L30=J$31)*10*($A$25=2) -> 0 | K30: =($L30=K$31)*10*($A$25=2) -> 0 | L30: {=INDEX(CHOOSE($A$25,$E$34:$E$38,$E$41:$E$45),A38)} -> 2 | M30: {=INDEX(CHOOSE($A$25,$F$34:$F$38,$F$41:$F$45),A38)} -> Michael | N30: =CHOOSE($A$25,G38,TEXT(G45,"0%")) -> 18087 | O30: =CHOOSE($A$25,"",G45)
A31: Leaderboard | B31: 1 | C31: 2 | D31: 3 | E31: 4 | F31: 5 | G31: 1 | H31: 2 | I31: 3 | J31: 4 | K31: 5
B33: Sales Team | C33: Value1 | E33: Sort
A34: 1 | B34: Ethan | C34: =GETPIVOTDATA(""&B34,Control!$A$3) -> 23076 | E34: {=_xlfn._xlws.SORT(A34:C38,3,-1)} -> 1 | F34: Ethan | G34: 23076
A35: 2 | B35: Michael | C35: =GETPIVOTDATA(""&B35,Control!$A$3) -> 18087 | E35: 3 | F35: James | G35: 22452
A36: 3 | B36: James | C36: =GETPIVOTDATA(""&B36,Control!$A$3) -> 22452 | E36: 5 | F36: Emma | G36: 20737
A37: 4 | B37: Olivia | C37: =GETPIVOTDATA(""&B37,Control!$A$3) -> 19334 | E37: 4 | F37: Olivia | G37: 19334
A38: 5 | B38: Emma | C38: =GETPIVOTDATA(""&B38,Control!$A$3) -> 20737 | E38: 2 | F38: Michael | G38: 18087
B40: Marketing Team | C40: Value2 | E40: Sort
A41: 1 | B41: Daniel | C41: =GETPIVOTDATA(""&B41,Control!$A$3) -> 1.02 | E41: {=_xlfn._xlws.SORT(A41:C45,3,-1)} -> 3 | F41: Sophia | G41: 1.26
A42: 2 | B42: Ryan | C42: =GETPIVOTDATA(""&B42,Control!$A$3) -> 1.21 | E42: 2 | F42: Ryan | G42: 1.21
A43: 3 | B43: Sophia | C43: =GETPIVOTDATA(""&B43,Control!$A$3) -> 1.26 | E43: 1 | F43: Daniel | G43: 1.02
...

Sheet Control
A3: Row Labels | B3: Sum of Prev Leads | C3: Sum of Prev MQL | D3: Sum of Prev SQL | E3: Sum of Prev Opportunity | F3: Sum of Prev Deals | G3: Sum of Leads | H3: Sum of MQL | I3: Sum of SQL | J3: Sum of Opportunity | K3: Sum of Deals | L3: Sum of Won Deals | M3: Sum of Pending | N3: Sum of Lost | O3: Sum of Revenue | P3: Sum of Forecast | Q3: Sum of Proposal | R3: Sum of Negotiation | S3: Sum of Proposal Count | T3: Sum of Negotiation Count | U3: Sum of Qualify | V3: Average of Sun | W3: Average of Mon | X3: Average of Tue | Y3: Sum of Wed | Z3: Average of Thu | AA3: Average of Fri | AB3: Average of Sat | AC3: Average of Retention Rate | AD3: Average of 1 | AE3: Average of 2 | AF3: Average of 3 | AG3: Average of 4 | AH3: Average of 5 | AI3: Average of 6 | AJ3: Average of 7 | AK3: Average of 11 | AL3: Average of 12 | AM3: Average of 13 | AN3: Average of 14 | AO3: Average of 15 | AP3: Average of 16 | AQ3: Average of 17 | AR3: Average of Duration | AS3: Average of Risk Aging | AT3: Sum of Ethan | AU3: Sum of Michael | AV3: Sum of James | AW3: Sum of Olivia | AX3: Sum of Emma | AY3: Average of Daniel | AZ3: Average of Ryan | BA3: Average of Sophia | BB3: Average of Ava | BC3: Average of Madison
A4: OCT | B4: 2986 | C4: 865 | D4: 573 | E4: 305 | F4: 95 | G4: 1223 | H4: 642 | I4: 491 | J4: 229 | K4: 78 | L4: 103686 | M4: 192011 | N4: 19201 | O4: 650203 | P4: 850387 | Q4: 499863 | R4: 443276 | S4: 159 | T4: 123 | U4: 776529 | V4: 0.1 | W4: 0.1 | X4: 0.15 | Y4: 0.18 | Z4: 0.15 | AA4: 0.14 | AB4: 0.17 | AC4: 0.61 | AD4: 1 | AE4: 0.6 | AF4: 0.51 | AG4: 0.79 | AH4: 0.69 | AI4: 0.4 | AJ4: 0.01 | AK4: 0.12 | AL4: 0.34 | AM4: 0.3 | AN4: 0.44 | AO4: 0.48 | AP4: 0.56 | AQ4: 1 | AR4: 5.4 | AS4: 0.14 | AT4: 23076 | AU4: 18087 | AV4: 22452 | AW4: 19334 | AX4: 20737 | AY4: 1.02 | AZ4: 1.21 | BA4: 1.26 | BB4: 0.96 | BC4: 0.89
A5: Grand Total | B5: 2986 | C5: 865 | D5: 573 | E5: 305 | F5: 95 | G5: 1223 | H5: 642 | I5: 491 | J5: 229 | K5: 78 | L5: 103686 | M5: 192011 | N5: 19201 | O5: 650203 | P5: 850387 | Q5: 499863 | R5: 443276 | S5: 159 | T5: 123 | U5: 776529 | V5: 0.1 | W5: 0.1 | X5: 0.15 | Y5: 0.18 | Z5: 0.15 | AA5: 0.14 | AB5: 0.17 | AC5: 0.61 | AD5: 1 | AE5: 0.6 | AF5: 0.51 | AG5: 0.79 | AH5: 0.69 | AI5: 0.4 | AJ5: 0.01 | AK5: 0.12 | AL5: 0.34 | AM5: 0.3 | AN5: 0.44 | AO5: 0.48 | AP5: 0.56 | AQ5: 1 | AR5: 5.4 | AS5: 0.14 | AT5: 23076 | AU5: 18087 | AV5: 22452 | AW5: 19334 | AX5: 20737 | AY5: 1.02 | AZ5: 1.21 | BA5: 1.26 | BB5: 0.96 | BC5: 0.89
A20: Row Labels | B20: Sum of Revenue | C20: Sum of Forecast
A21: JAN | B21: 620194 | C21: 950198
A22: FEB | B22: 750285 | C22: 800198
A23: MAR | B23: 880309 | C23: 700366
A24: APR | B24: 1020288 | C24: 650158
A25: MAY | B25: 1150282 | C25: 550211
A26: JUN | B26: 1100350 | C26: 600367
A27: JUL | B27: 950350 | C27: 750365
A28: AUG | B28: 850346 | C28: 900163
A29: SEP | B29: 700391 | C29: 1000261
A30: OCT | B30: 650203 | C30: 850387
A31: NOV | B31: 800355 | C31: 700382
A32: DEC | B32: 900113 | C32: 600384
A33: Grand Total | B33: 10373466 | C33: 9053440
A37: Row Labels | B37: Sum of Value
A38: Proposal | B38: 588164
A39: Grand Total | B39: 588164
A44: Row Labels | B44: Sum of Weekly Activity
A45: Wed | B45: 0.2
A46: Grand Total | B46: 0.2

Sheet Data
A1: Year | B1: Month | C1: Prev Leads | D1: Prev MQL | E1: Prev SQL | F1: Prev Opportunity | G1: Prev Deals | H1: Leads | I1: MQL | J1: SQL | K1: Opportunity | L1: Deals | M1: Won Deals | N1: Pending | O1: Lost | P1: Revenue | Q1: Forecast | R1: Qualify | S1: Proposal | T1: Negotiation | U1: Qualify Count | V1: Proposal Count | W1: Negotiation Count | X1: Sun | Y1: Mon | Z1: Tue | AA1: Wed | AB1: Thu | AC1: Fri | AD1: Sat | AE1: Retention Rate | AF1: 1 | AG1: 2 | AH1: 3 | AI1: 4 | AJ1: 5 | AK1: 6 | AL1: 7 | AM1: 11 | AN1: 12 | AO1: 13 | AP1: 14 | AQ1: 15 | AR1: 16 | AS1: 17 | AT1: Duration | AU1: Risk Aging | AV1: Ethan | AW1: Michael | AX1: James | AY1: Olivia | AZ1: Emma | BA1: Daniel | BB1: Ryan | BC1: Sophia | BD1: Ava | BE1: Madison
A2: 2028 | B2: JAN | C2: 0 | D2: 0 | E2: 0 | F2: 0 | G2: 0 | H2: 2630 | I2: 897 | J2: 487 | K2: 263 | L2: 150 | M2: 231230 | N2: 412910 | O2: 70195 | P2: 500152 | Q2: 500171 | R2: 524393 | S2: 454255 | T2: 391700 | U2: 263 | V2: 207 | W2: 178 | X2: 0.11875 | Y2: 0.09375 | Z2: 0.14375 | AA2: 0.175 | AB2: 0.1625 | AC2: 0.1375 | AD2: 0.16875 | AE2: 0.68 | AF2: 1 | AG2: 0.7 | AH2: 0.6 | AI2: 0.7 | AJ2: 0.6 | AK2: 0.4 | AL2: 0.05 | AM2: 0.1 | AN2: 0.4 | AO2: 0.25 | AP2: 0.5 | AQ2: 0.4 | AR2: 0.6 | AS2: 1 | AT2: 5.5 | AU2: 0.13 | AV2: 50710 | AW2: 51424 | AX2: 45710 | AY2: 37140 | AZ2: 46246 | BA2: 0.79 | BB2: 1.17 | BC2: 1.11 | BD2: 1.03 | BE2: 1.23
A3: 2028 | B3: FEB | C3: =H2 -> 2630 | D3: =I2 -> 897 | E3: =J2 -> 487 | F3: =K2 -> 263 | G3: =L2 -> 150 | H3: 3216 | I3: 886 | J3: 486 | K3: 231 | L3: 107 | M3: 403930 | N3: 504912 | O3: 55540 | P3: 400386 | Q3: 425258 | R3: 530769 | S3: 520895 | T3: 360977 | U3: 231 | V3: 169 | W3: 138 | X3: 0.13 | Y3: 0.1 | Z3: 0.13 | AA3: 0.16 | AB3: 0.18 | AC3: 0.15 | AD3: 0.15 | AE3: 0.67 | AF3: 1 | AG3: 0.8 | AH3: 0.68 | AI3: 0.61 | AJ3: 0.54 | AK3: 0.33 | AL3: 0.05 | AM3: 0.08 | AN3: 0.37 | AO3: 0.21 | AP3: 0.42 | AQ3: 0.36 | AR3: 0.68 | AS3: 1 | AT3: 4.9 | AU3: 0.18 | AV3: 76262 | AW3: 71092 | AX3: 82725 | AY3: 93065 | AZ3: 80786 | BA3: 1.03 | BB3: 0.92 | BC3: 0.8 | BD3: 1.15 | BE3: 0.78
A4: 2028 | B4: MAR | C4: =H3 -> 3216 | D4: =I3 -> 886 | E4: =J3 -> 486 | F4: =K3 -> 231 | G4: =L3 -> 107 | H4: 1798 | I4: 887 | J4: 462 | K4: 286 | L4: 99 | M4: 194777 | N4: 282286 | O4: 22583 | P4: 500386 | Q4: 650124 | R4: 547776 | S4: 404116 | T4: 362188 | U4: 286 | V4: 193 | W4: 146 | X4: 0.12 | Y4: 0.09 | Z4: 0.13 | AA4: 0.19 | AB4: 0.17 | AC4: 0.16 | AD4: 0.16 | AE4: 0.66 | AF4: 1 | AG4: 0.63 | AH4: 0.52 | AI4: 0.7 | AJ4: 0.69 | AK4: 0.44 | AL4: 0.11 | AM4: 0.11 | AN4: 0.35 | AO4: 0.21 | AP4: 0.58 | AQ4: 0.33 | AR4: 0.52 | AS4: 1 | AT4: 5.2 | AU4: 0.11 | AV4: 51177 | AW4: 41247 | AX4: 29789 | AY4: 33609 | AZ4: 38955 | BA4: 0.98 | BB4: 0.88 | BC4: 0.92 | BD4: 0.73 | BE4: 0.88
A5: 2028 | B5: APR | C5: =H4 -> 1798 | D5: =I4 -> 887 | E5: =J4 -> 462 | F5: =K4 -> 286 | G5: =L4 -> 99 | H5: 1495 | I5: 811 | J5: 511 | K5: 262 | L5: 120 | M5: 178383 | N5: 234715 | O5: 21124 | P5: 450195 | Q5: 500245 | R5: 654737 | S5: 529102 | T5: 445313 | U5: 262 | V5: 191 | W5: 155 | X5: 0.12 | Y5: 0.09 | Z5: 0.14 | AA5: 0.18 | AB5: 0.16 | AC5: 0.14 | AD5: 0.17 | AE5: 0.72 | AF5: 1 | AG5: 0.67 | AH5: 0.53 | AI5: 0.61 | AJ5: 0.53 | AK5: 0.36 | AL5: 0.07 | AM5: 0.13 | AN5: 0.45 | AO5: 0.27 | AP5: 0.59 | AQ5: 0.33 | AR5: 0.57 | AS5: 1 | AT5: 4.9 | AU5: 0.16 | AV5: 39432 | AW5: 41310 | AX5: 16274 | AY5: 45691 | AZ5: 35676 | BA5: 0.84 | BB5: 1.03 | BC5: 0.78 | BD5: 1.13 | BE5: 0.78
A6: 2028 | B6: MAY | C6: =H5 -> 1495 | D6: =I5 -> 811 | E6: =J5 -> 511 | F6: =K5 -> 262 | G6: =L5 -> 120 | H6: 2832 | I6: 842 | J6: 352 | K6: 255 | L6: 142 | M6: 257882 | N6: 444624 | O6: 26677 | P6: 700271 | Q6: 730303 | R6: 675024 | S6: 639288 | T6: 391909 | U6: 255 | V6: 199 | W6: 170 | X6: 0.14 | Y6: 0.09 | Z6: 0.14 | AA6: 0.18 | AB6: 0.09 | AC6: 0.15 | AD6: 0.19 | AE6: 0.73 | AF6: 1 | AG6: 0.76 | AH6: 0.56 | AI6: 0.78 | AJ6: 0.51 | AK6: 0.33 | AL6: 0.01 | AM6: 0.07 | AN6: 0.39 | AO6: 0.2 | AP6: 0.51 | AQ6: 0.35 | AR6: 0.54 | AS6: 1 | AT6: 5.1 | AU6: 0.19 | AV6: 57307 | AW6: 43390 | AX6: 46664 | AY6: 58944 | AZ6: 51577 | BA6: 0.97 | BB6: 0.85 | BC6: 0.75 | BD6: 1.06 | BE6: 1.22
A7: 2028 | B7: JUN | C7: =H6 -> 2832 | D7: =I6 -> 842 | E7: =J6 -> 352 | F7: =K6 -> 255 | G7: =L6 -> 142 | H7: 1392 | I7: 656 | J7: 328 | K7: 251 | L7: 92 | M7: 135497 | N7: 218544 | O7: 10927 | P7: 600209 | Q7: 650339 | R7: 681543 | S7: 420284 | T7: 425958 | U7: 251 | V7: 217 | W7: 199 | X7: 0.1 | Y7: 0.13 | Z7: 0.08 | AA7: 0.07 | AB7: 0.15 | AC7: 0.15 | AD7: 0.15 | AE7: 0.66 | AF7: 1 | AG7: 0.81 | AH7: 0.53 | AI7: 0.74 | AJ7: 0.69 | AK7: 0.45 | AL7: 0.09 | AM7: 0.11 | AN7: 0.42 | AO7: 0.28 | AP7: 0.55 | AQ7: 0.34 | AR7: 0.66 | AS7: 1 | AT7: 5.3 | AU7: 0.08 | AV7: 14648 | AW7: 31250 | AX7: 28808 | AY7: 33691 | AZ7: 27100 | BA7: 0.99 | BB7: 0.76 | BC7: 0.89 | BD7: 0.86 | BE7: 1.03
A8: 2028 | B8: JUL | C8: =H7 -> 1392 | D8: =I7 -> 656 | E8: =J7 -> 328 | F8: =K7 -> 251 | G8: =L7 -> 92 | H8: 1079 | I8: 696 | J8: 433 | K8: 236 | L8: 107 | M8: 128746 | N8: 169403 | O8: 28799 | P8: 800122 | Q8: 700346 | R8: 747155 | S8: 419631 | T8: 521248 | U8: 236 | V8: 172 | W8: 139 | X8: 0.12 | Y8: 0.1 | Z8: 0.13 | AA8: 0.17 | AB8: 0.16 | AC8: 0.14 | AD8: 0.19 | AE8: 0.82 | AF8: 1 | AG8: 0.62 | AH8: 0.55 | AI8: 0.62 | AJ8: 0.6 | AK8: 0.46 | AL8: 0.02 | AM8: 0.08 | AN8: 0.42 | AO8: 0.29 | AP8: 0.56 | AQ8: 0.35 | AR8: 0.65 | AS8: 1 | AT8: 5.9 | AU8: 0.2 | AV8: 14137 | AW8: 22720 | AX8: 35847 | AY8: 30293 | AZ8: 25749 | BA8: 1.16 | BB8: 0.9 | BC8: 1.1 | BD8: 1.06 | BE8: 1.19
A9: 2028 | B9: AUG | C9: =H8 -> 1079 | D9: =I8 -> 696 | E9: =J8 -> 433 | F9: =K8 -> 236 | G9: =L8 -> 107 | H9: 1334 | I9: 645 | J9: 481 | K9: 271 | L9: 45 | M9: 108908 | N9: 209438 | O9: 25133 | P9: 700188 | Q9: 820346 | R9: 806412 | S9: 638689 | T9: 444633 | U9: 271 | V9: 173 | W9: 124 | X9: 0.12 | Y9: 0.09 | Z9: 0.17 | AA9: 0.18 | AB9: 0.16 | AC9: 0.12 | AD9: 0.18 | AE9: 0.79 | AF9: 1 | AG9: 0.61 | AH9: 0.51 | AI9: 0.63 | AJ9: 0.67 | AK9: 0.33 | AL9: 0.08 | AM9: 0.1 | AN9: 0.44 | AO9: 0.18 | AP9: 0.5 | AQ9: 0.42 | AR9: 0.53 | AS9: 1 | AT9: 4.2 | AU9: 0.07 | AV9: 29172 | AW9: 12836 | AX9: 22171 | AY9: 22948 | AZ9: 21781 | BA9: 0.72 | BB9: 0.72 | BC9: 1.05 | BD9: 0.9 | BE9: 0.96
A10: 2028 | B10: SEP | C10: =H9 -> 1334 | D10: =I9 -> 645 | E10: =J9 -> 481 | F10: =K9 -> 271 | G10: =L9 -> 45 | H10: 1140 | I10: 779 | J10: 324 | K10: 254 | L10: 67 | M10: 128866 | N10: 178980 | O10: 12529 | P10: 800256 | Q10: 770330 | R10: 671658 | S10: 596726 | T10: 465454 | U10: 254 | V10: 176 | W10: 136 | X10: 0.13 | Y10: 0.12 | Z10: 0.14 | AA10: 0.13 | AB10: 0.1 | AC10: 0.14 | AD10: 0.07 | AE10: 0.66 | AF10: 1 | AG10: 0.78 | AH10: 0.55 | AI10: 0.61 | AJ10: 0.56 | AK10: 0.31 | AL10: 0.02 | AM10: 0.14 | AN10: 0.43 | AO10: 0.19 | AP10: 0.54 | AQ10: 0.38 | AR10: 0.56 | AS10: 1 | AT10: 4.8 | AU10: 0.14 | AV10: 36779 | AW10: 26191 | AX10: 15603 | AY10: 24519 | AZ10: 25774 | BA10: 1.03 | BB10: 0.74 | BC10: 0.89 | BD10: 0.76 | BE10: 0.75
A11: 2028 | B11: OCT | C11: =H10 -> 1140 | D11: =I10 -> 779 | E11: =J10 -> 324 | F11: =K10 -> 254 | G11: =L10 -> 67 | H11: 1745 | I11: 798 | J11: 593 | K11: 270 | L11: 126 | M11: 199994 | N11: 273965 | O11: 38355 | P11: 1000333 | Q11: 900175 | R11: 752643 | S11: 423299 | T11: 508048 | U11: 270 | V11: 203 | W11: 169 | X11: 0.13 | Y11: 0.1 | Z11: 0.13 | AA11: 0.19 | AB11: 0.19 | AC11: 0.13 | AD11: 0.18 | AE11: 0.83 | AF11: 1 | AG11: 0.6 | AH11: 0.54 | AI11: 0.75 | AJ11: 0.52 | AK11: 0.47 | AL11: 0.08 | AM11: 0.06 | AN11: 0.48 | AO11: 0.28 | AP11: 0.47 | AQ11: 0.48 | AR11: 0.51 | AS11: 1 | AT11: 4.2 | AU11: 0.14 | AV11: 29357 | AW11: 31559 | AX11: 49173 | AY11: 49907 | AZ11: 39998 | BA11: 1.1 | BB11: 0.73 | BC11: 1.06 | BD11: 0.71 | BE11: 1.28
A12: 2028 | B12: NOV | C12: =H11 -> 1745 | D12: =I11 -> 798 | E12: =J11 -> 593 | F12: =K11 -> 270 | G12: =L11 -> 126 | H12: 2106 | I12: 818 | J12: 543 | K12: 210 | L12: 93 | M12: 201692 | N12: 330642 | O12: 16532 | P12: 950247 | Q12: 850218 | R12: 836394 | S12: 466809 | T12: 418070 | U12: 210 | V12: 171 | W12: 151 | X12: 0.13 | Y12: 0.11 | Z12: 0.17 | AA12: 0.15 | AB12: 0.16 | AC12: 0.17 | AD12: 0.18 | AE12: 0.8 | AF12: 1 | AG12: 0.79 | AH12: 0.66 | AI12: 0.64 | AJ12: 0.66 | AK12: 0.46 | AL12: 0.09 | AM12: 0.12 | AN12: 0.37 | AO12: 0.2 | AP12: 0.55 | AQ12: 0.34 | AR12: 0.63 | AS12: 1 | AT12: 5.3 | AU12: 0.19 | AV12: 44091 | AW12: 43153 | AX12: 31895 | AY12: 42215 | AZ12: 40338 | BA12: 1.07 | BB12: 0.89 | BC12: 1 | BD12: 1.14 | BE12: 0.97
A13: 2028 | B13: DEC | C13: =H12 -> 2106 | D13: =I12 -> 818 | E13: =J12 -> 543 | F13: =K12 -> 210 | G13: =L12 -> 93 | H13: 2768 | I13: 745 | J13: 428 | K13: 259 | L13: 123 | M13: 269437 | N13: 434576 | O13: 30420 | P13: 800359 | Q13: 1000316 | R13: 817104 | S13: 590508 | T13: 368448 | U13: 259 | V13: 191 | W13: 157 | X13: 0.12 | Y13: 0.09 | Z13: 0.13 | AA13: 0.15 | AB13: 0.15 | AC13: 0.19 | AD13: 0.17 | AE13: 0.7 | AF13: 1 | AG13: 0.66 | AH13: 0.64 | AI13: 0.79 | AJ13: 0.54 | AK13: 0.31 | AL13: 0.11 | AM13: 0.1 | AN13: 0.34 | AO13: 0.31 | AP13: 0.53 | AQ13: 0.47 | AR13: 0.64 | AS13: 1 | AT13: 5.6 | AU13: 0.12 | AV13: 39191 | AW13: 61458 | AX13: 54333 | AY13: 60568 | AZ13: 53887 | BA13: 0.91 | BB13: 1.23 | BC13: 0.95 | BD13: 0.73 | BE13: 1.12
A14: 2029 | B14: JAN | C14: =H13 -> 2768 | D14: =I13 -> 745 | E14: =J13 -> 428 | F14: =K13 -> 259 | G14: =L13 -> 123 | H14: 2919 | I14: 848 | J14: 491 | K14: 210 | L14: 107 | M14: 297884 | N14: 458283 | O14: 50411 | P14: 620194 | Q14: 950198 | R14: 847277 | S14: 423312 | T14: 359575 | U14: 210 | V14: 169 | W14: 148 | X14: 0.12 | Y14: 0.1 | Z14: 0.14 | AA14: 0.19 | AB14: 0.14 | AC14: 0.15 | AD14: 0.17 | AE14: 0.61 | AF14: 1 | AG14: 0.79 | AH14: 0.65 | AI14: 0.76 | AJ14: 0.54 | AK14: 0.45 | AL14: 0.04 | AM14: 0.1 | AN14: 0.45 | AO14: 0.31 | AP14: 0.52 | AQ14: 0.37 | AR14: 0.68 | AS14: 1 | AT14: 5 | AU14: 0.17 | AV14: 50675 | AW14: 38348 | AX14: 61631 | AY14: 87653 | AZ14: 59577 | BA14: 1.21 | BB14: 1.18 | BC14: 0.96 | BD14: 1.06 | BE14: 1.08
... A37: 2030 | B37: DEC | C37: =H36 -> 1167 | D37: =I36 -> 690 | E37: =J36 -> 459 | F37: =K36 -> 220 | G37: =L36 -> 114 | H37: 1646 | I37: 804 | J37: 360 | K37: 285 | L37: 105 | M37: 162806 | N37: 258422 | O37: 23258 | P37: 1000371 | Q37: 1100263 | R37: 618914 | S37: 569515 | T37: 412427 | U37: 285 | V37: 206 | W37: 166 | X37: 0.12 | Y37: 0.09 | Z37: 0.14 | AA37: 0.17 | AB37: 0.17 | AC37: 0.12 | AD37: 0.16 | AE37: 0.75 | AF37: 1 | AG37: 0.74 | AH37: 0.51 | AI37: 0.79 | AJ37: 0.67 | AK37: 0.34 | AL37: 0.07 | AM37: 0.09 | AN37: 0.4 | AO37: 0.27 | AP37: 0.53 | AQ37: 0.44 | AR37: 0.7 | AS37: 1 | AT37: 5.1 | AU37: 0.13 | AV37: 25457 | AW37: 39073 | AX37: 24273 | AY37: 41442 | AZ37: 32561 | BA37: 1.13 | BB37: 1.24 | BC37: 1.08 | BD37: 1.03 | BE37: 1.09

Sheet Resources
B1: Colors | C1: Position | D1: Angle | E1: Transparency | G1: Shadow | O1: $#,##0;-$#,##0;0 | R1: [>=1000]0,"k";[<=-1000]-0,"k";0
B2: #0D0C15 | D2: 0 | G2: 50 | H2: 100 | I2: 15 | J2: 135 | K2: 20
B3: #12111E | D3: 0 | G3: 20 | H3: 100 | I3: 10 | J3: 135 | K3: 15
B4: #0F0F1B | D4: 0 | G4: Leads | H4: MQL | I4: SQL | J4: Opportunity | K4: Deals
B5: #282A3E | D5: 0 | G5: ="Prev "&G4 -> Prev Leads | H5: ="Prev "&H4 -> Prev MQL | I5: ="Prev "&I4 -> Prev SQL | J5: ="Prev "&J4 -> Prev Opportunity | K5: ="Prev "&K4 -> Prev Deals
B6: #111320 | D6: 0
A7: Line | B7: #3E4060 | C7: 12 | D7: 0
A8: Line | B8: #3399FF | C8: 23 | D8: 0
A9: Line | B9: #2C2E44 | C9: 34 | D9: 0
A10: Line | B10: #FFE1FF | C10: 64 | D10: 0
A11: Line | B11: #C05BE9 | C11: 75 | D11: 0
A12: Line | B12: #3E4060 | C12: 93 | D12: 0
B14: #161A28 | C14: 44 | D14: 0
B15: #1E2133 | C15: 100 | D15: 0
A16: Line | B16: #5F6193 | D16: 0
B19: #161A28 | C19: 35 | D19: 45
B20: #232539 | C20: 54 | D20: 45
B21: #944247 | C21: 84 | D21: 45
B22: #E14856 | C22: 100 | D22: 45
A23: Line | B23: #FFFFFF | C23: 0 | D23: 250
A24: Line | B24: #F9B7B1 | C24: 13 | D24: 250
A25: Line | B25: #1C1F31 | C25: 48 | D25: 250
B27: #161A28 | C27: 35 | D27: 45
B28: #232539 | C28: 54 | D28: 45
B29: #B335B9 | C29: 84 | D29: 45
B30: #FE02CE | C30: 100 | D30: 45
A31: Line | B31: #FFFFFF | C31: 0 | D31: 250
A32: Line | B32: #F9B7B1 | C32: 13 | D32: 250
A33: Line | B33: #1C1F31 | C33: 48 | D33: 250
B35: #161A28 | C35: 35 | D35: 45
B36: #232539 | C36: 54 | D36: 45
B37: #B335B9 | C37: 84 | D37: 45
B38: #FE02CE | C38: 100 | D38: 45
A39: Line | B39: #FFFFFF | C39: 0 | D39: 250
A40: Line | B40: #F9B7B1 | C40: 13 | D40: 250
A41: Line | B41: #1C1F31 | C41: 48 | D41: 250
B43: #161A28 | C43: 35 | D43: 45
B44: #232539 | C44: 54 | D44: 45
B45: #B335B9 | C45: 84 | D45: 45
B46: #FE02CE | C46: 100 | D46: 45
...
